Failure # 1 (occurred at 2024-05-15_09-06-07)
The actor died because of an error raised in its creation task, [36mray::PPO.__init__()[39m (pid=13649, ip=192.168.1.56, actor_id=0b0450d90a301440d0afa9f001000000, repr=PPO)
  File "/home/valapeos/.cache/pypoetry/virtualenvs/pneumarl-4s6AwDM4-py3.11/lib/python3.11/site-packages/ray/rllib/env/env_runner_group.py", line 239, in _setup
    self.add_workers(
  File "/home/valapeos/.cache/pypoetry/virtualenvs/pneumarl-4s6AwDM4-py3.11/lib/python3.11/site-packages/ray/rllib/env/env_runner_group.py", line 754, in add_workers
    raise result.get()
  File "/home/valapeos/.cache/pypoetry/virtualenvs/pneumarl-4s6AwDM4-py3.11/lib/python3.11/site-packages/ray/rllib/utils/actor_manager.py", line 497, in _fetch_result
    result = ray.get(r)
             ^^^^^^^^^^
           ^^^^^^^^^^^^^^^^^^^
           ^^^^^^^^^^^^^^^^^^^^^
                                  ^^^^^^^^^^^^^^^^^^^^^^^^^^^^^^^^^^^^^^^^^^^^^^^^
ray.exceptions.ActorDiedError: The actor died because of an error raised in its creation task, [36mray::RolloutWorker.__init__()[39m (pid=13721, ip=192.168.1.56, actor_id=cf76be01afb9954787ceb84801000000, repr=<ray.rllib.evaluation.rollout_worker.RolloutWorker object at 0x7fd32a36abd0>)
           ^^^^^^^^^^^^^^^^^^^^^^^^^^^^^^^^^^^^
           ^^^^^^^^^^^^^^^^^^^^^^^^^^^^^^^
  File "/home/valapeos/.cache/pypoetry/virtualenvs/pneumarl-4s6AwDM4-py3.11/lib/python3.11/site-packages/ray/rllib/evaluation/rollout_worker.py", line 407, in __init__
    self.env = env_creator(copy.deepcopy(self.env_context))
               ^^^^^^^^^^^^^^^^^^^^^^^^^^^^^^^^^^^^^^^^^^^^
  File "/home/valapeos/Projects/pneumarl/rllib_example.py", line 48, in env_creator
    return RayVectorGodotEnv(config=env_config, port=port, seed=seed)
           ^^^^^^^^^^^^^^^^^^^^^^^^^^^^^^^^^^^^^^^^^^^^^^^^^^^^^^^^^^
  File "/home/valapeos/.cache/pypoetry/virtualenvs/pneumarl-4s6AwDM4-py3.11/lib/python3.11/site-packages/godot_rl/wrappers/ray_wrapper.py", line 22, in __init__
    self._env = GodotEnv(
                ^^^^^^^^^
  File "/home/valapeos/.cache/pypoetry/virtualenvs/pneumarl-4s6AwDM4-py3.11/lib/python3.11/site-packages/godot_rl/core/godot_env.py", line 59, in __init__
    self.connection = self._start_server()
                      ^^^^^^^^^^^^^^^^^^^^
  File "/home/valapeos/.cache/pypoetry/virtualenvs/pneumarl-4s6AwDM4-py3.11/lib/python3.11/site-packages/godot_rl/core/godot_env.py", line 317, in _start_server
    connection, client_address = sock.accept()
                                 ^^^^^^^^^^^^^
  File "/nix/store/glfr70gi7hfaj50mwj2431p8bg60fhqw-python3-3.11.9/lib/python3.11/socket.py", line 294, in accept
    fd, addr = self._accept()
               ^^^^^^^^^^^^^^
TimeoutError: timed out

During handling of the above exception, another exception occurred:

[36mray::PPO.__init__()[39m (pid=13649, ip=192.168.1.56, actor_id=0b0450d90a301440d0afa9f001000000, repr=PPO)
           ^^^^^^^^^^^^^^^^^^^^^^^^^^^^^^^^^^^^
           ^^^^^^^^^^^^^^^^^^^^^^^^^^^^^^^
  File "/home/valapeos/.cache/pypoetry/virtualenvs/pneumarl-4s6AwDM4-py3.11/lib/python3.11/site-packages/ray/rllib/algorithms/algorithm.py", line 554, in __init__
    super().__init__(
  File "/home/valapeos/.cache/pypoetry/virtualenvs/pneumarl-4s6AwDM4-py3.11/lib/python3.11/site-packages/ray/tune/trainable/trainable.py", line 158, in __init__
    self.setup(copy.deepcopy(self.config))
           ^^^^^^^^^^^^^^^^^^^^^^^^^^^^^^^
  File "/home/valapeos/.cache/pypoetry/virtualenvs/pneumarl-4s6AwDM4-py3.11/lib/python3.11/site-packages/ray/rllib/algorithms/algorithm.py", line 640, in setup
    self.workers = EnvRunnerGroup(
                   ^^^^^^^^^^^^^^^
  File "/home/valapeos/.cache/pypoetry/virtualenvs/pneumarl-4s6AwDM4-py3.11/lib/python3.11/site-packages/ray/rllib/env/env_runner_group.py", line 191, in __init__
    raise e.args[0].args[2]
TimeoutError: timed out
