:job_id:01000000
:actor_name:PPO
2024-05-15 09:05:04,706	WARNING deprecation.py:50 -- DeprecationWarning: `AlgorithmConfig.num_envs_per_worker` has been deprecated. Use `AlgorithmConfig.num_envs_per_env_runner` instead. This will raise an error in the future!
2024-05-15 09:05:04,711	WARNING deprecation.py:50 -- DeprecationWarning: `WorkerSet(num_workers=... OR local_worker=...)` has been deprecated. Use `EnvRunnerGroup(num_env_runners=... AND local_env_runner=...)` instead. This will raise an error in the future!
2024-05-15 09:05:04,711	WARNING deprecation.py:50 -- DeprecationWarning: `max_num_worker_restarts` has been deprecated. Use `AlgorithmConfig.max_num_env_runner_restarts` instead. This will raise an error in the future!
2024-05-15 09:06:07,046	ERROR actor_manager.py:519 -- Ray error, taking actor 1 out of service. The actor died because of an error raised in its creation task, [36mray::RolloutWorker.__init__()[39m (pid=13721, ip=192.168.1.56, actor_id=cf76be01afb9954787ceb84801000000, repr=<ray.rllib.evaluation.rollout_worker.RolloutWorker object at 0x7fd32a36abd0>)
           ^^^^^^^^^^^^^^^^^^^^^^^^^^^^^^^^^^^^
           ^^^^^^^^^^^^^^^^^^^^^^^^^^^^^^^
  File "/home/valapeos/.cache/pypoetry/virtualenvs/pneumarl-4s6AwDM4-py3.11/lib/python3.11/site-packages/ray/rllib/evaluation/rollout_worker.py", line 407, in __init__
    self.env = env_creator(copy.deepcopy(self.env_context))
               ^^^^^^^^^^^^^^^^^^^^^^^^^^^^^^^^^^^^^^^^^^^^
  File "/home/valapeos/Projects/pneumarl/rllib_example.py", line 48, in env_creator
    return RayVectorGodotEnv(config=env_config, port=port, seed=seed)
           ^^^^^^^^^^^^^^^^^^^^^^^^^^^^^^^^^^^^^^^^^^^^^^^^^^^^^^^^^^
  File "/home/valapeos/.cache/pypoetry/virtualenvs/pneumarl-4s6AwDM4-py3.11/lib/python3.11/site-packages/godot_rl/wrappers/ray_wrapper.py", line 22, in __init__
    self._env = GodotEnv(
                ^^^^^^^^^
  File "/home/valapeos/.cache/pypoetry/virtualenvs/pneumarl-4s6AwDM4-py3.11/lib/python3.11/site-packages/godot_rl/core/godot_env.py", line 59, in __init__
    self.connection = self._start_server()
                      ^^^^^^^^^^^^^^^^^^^^
  File "/home/valapeos/.cache/pypoetry/virtualenvs/pneumarl-4s6AwDM4-py3.11/lib/python3.11/site-packages/godot_rl/core/godot_env.py", line 317, in _start_server
    connection, client_address = sock.accept()
                                 ^^^^^^^^^^^^^
  File "/nix/store/glfr70gi7hfaj50mwj2431p8bg60fhqw-python3-3.11.9/lib/python3.11/socket.py", line 294, in accept
    fd, addr = self._accept()
               ^^^^^^^^^^^^^^
TimeoutError: timed out
2024-05-15 09:06:07,046	ERROR actor_manager.py:519 -- Ray error, taking actor 2 out of service. The actor died because of an error raised in its creation task, [36mray::RolloutWorker.__init__()[39m (pid=13722, ip=192.168.1.56, actor_id=64110d8601f56bf14e9797c501000000, repr=<ray.rllib.evaluation.rollout_worker.RolloutWorker object at 0x7fd9bed37cd0>)
           ^^^^^^^^^^^^^^^^^^^^^^^^^^^^^^^^^^^^
           ^^^^^^^^^^^^^^^^^^^^^^^^^^^^^^^
  File "/home/valapeos/.cache/pypoetry/virtualenvs/pneumarl-4s6AwDM4-py3.11/lib/python3.11/site-packages/ray/rllib/evaluation/rollout_worker.py", line 407, in __init__
    self.env = env_creator(copy.deepcopy(self.env_context))
               ^^^^^^^^^^^^^^^^^^^^^^^^^^^^^^^^^^^^^^^^^^^^
  File "/home/valapeos/Projects/pneumarl/rllib_example.py", line 48, in env_creator
    return RayVectorGodotEnv(config=env_config, port=port, seed=seed)
           ^^^^^^^^^^^^^^^^^^^^^^^^^^^^^^^^^^^^^^^^^^^^^^^^^^^^^^^^^^
  File "/home/valapeos/.cache/pypoetry/virtualenvs/pneumarl-4s6AwDM4-py3.11/lib/python3.11/site-packages/godot_rl/wrappers/ray_wrapper.py", line 22, in __init__
    self._env = GodotEnv(
                ^^^^^^^^^
  File "/home/valapeos/.cache/pypoetry/virtualenvs/pneumarl-4s6AwDM4-py3.11/lib/python3.11/site-packages/godot_rl/core/godot_env.py", line 59, in __init__
    self.connection = self._start_server()
                      ^^^^^^^^^^^^^^^^^^^^
  File "/home/valapeos/.cache/pypoetry/virtualenvs/pneumarl-4s6AwDM4-py3.11/lib/python3.11/site-packages/godot_rl/core/godot_env.py", line 317, in _start_server
    connection, client_address = sock.accept()
                                 ^^^^^^^^^^^^^
  File "/nix/store/glfr70gi7hfaj50mwj2431p8bg60fhqw-python3-3.11.9/lib/python3.11/socket.py", line 294, in accept
    fd, addr = self._accept()
               ^^^^^^^^^^^^^^
TimeoutError: timed out
2024-05-15 09:06:07,046	ERROR actor_manager.py:519 -- Ray error, taking actor 3 out of service. The actor died because of an error raised in its creation task, [36mray::RolloutWorker.__init__()[39m (pid=13723, ip=192.168.1.56, actor_id=6c1e2f8e5911cf8ba4dcac5b01000000, repr=<ray.rllib.evaluation.rollout_worker.RolloutWorker object at 0x7f8dd32043d0>)
           ^^^^^^^^^^^^^^^^^^^^^^^^^^^^^^^^^^^^
           ^^^^^^^^^^^^^^^^^^^^^^^^^^^^^^^
  File "/home/valapeos/.cache/pypoetry/virtualenvs/pneumarl-4s6AwDM4-py3.11/lib/python3.11/site-packages/ray/rllib/evaluation/rollout_worker.py", line 407, in __init__
    self.env = env_creator(copy.deepcopy(self.env_context))
               ^^^^^^^^^^^^^^^^^^^^^^^^^^^^^^^^^^^^^^^^^^^^
  File "/home/valapeos/Projects/pneumarl/rllib_example.py", line 48, in env_creator
    return RayVectorGodotEnv(config=env_config, port=port, seed=seed)
           ^^^^^^^^^^^^^^^^^^^^^^^^^^^^^^^^^^^^^^^^^^^^^^^^^^^^^^^^^^
  File "/home/valapeos/.cache/pypoetry/virtualenvs/pneumarl-4s6AwDM4-py3.11/lib/python3.11/site-packages/godot_rl/wrappers/ray_wrapper.py", line 22, in __init__
    self._env = GodotEnv(
                ^^^^^^^^^
  File "/home/valapeos/.cache/pypoetry/virtualenvs/pneumarl-4s6AwDM4-py3.11/lib/python3.11/site-packages/godot_rl/core/godot_env.py", line 59, in __init__
    self.connection = self._start_server()
                      ^^^^^^^^^^^^^^^^^^^^
  File "/home/valapeos/.cache/pypoetry/virtualenvs/pneumarl-4s6AwDM4-py3.11/lib/python3.11/site-packages/godot_rl/core/godot_env.py", line 317, in _start_server
    connection, client_address = sock.accept()
                                 ^^^^^^^^^^^^^
  File "/nix/store/glfr70gi7hfaj50mwj2431p8bg60fhqw-python3-3.11.9/lib/python3.11/socket.py", line 294, in accept
    fd, addr = self._accept()
               ^^^^^^^^^^^^^^
TimeoutError: timed out
2024-05-15 09:06:07,046	ERROR actor_manager.py:519 -- Ray error, taking actor 4 out of service. The actor died because of an error raised in its creation task, [36mray::RolloutWorker.__init__()[39m (pid=13724, ip=192.168.1.56, actor_id=79760d3ce8052092d662e89401000000, repr=<ray.rllib.evaluation.rollout_worker.RolloutWorker object at 0x7f6d4fb09490>)
           ^^^^^^^^^^^^^^^^^^^^^^^^^^^^^^^^^^^^
           ^^^^^^^^^^^^^^^^^^^^^^^^^^^^^^^
  File "/home/valapeos/.cache/pypoetry/virtualenvs/pneumarl-4s6AwDM4-py3.11/lib/python3.11/site-packages/ray/rllib/evaluation/rollout_worker.py", line 407, in __init__
    self.env = env_creator(copy.deepcopy(self.env_context))
               ^^^^^^^^^^^^^^^^^^^^^^^^^^^^^^^^^^^^^^^^^^^^
  File "/home/valapeos/Projects/pneumarl/rllib_example.py", line 48, in env_creator
    return RayVectorGodotEnv(config=env_config, port=port, seed=seed)
           ^^^^^^^^^^^^^^^^^^^^^^^^^^^^^^^^^^^^^^^^^^^^^^^^^^^^^^^^^^
  File "/home/valapeos/.cache/pypoetry/virtualenvs/pneumarl-4s6AwDM4-py3.11/lib/python3.11/site-packages/godot_rl/wrappers/ray_wrapper.py", line 22, in __init__
    self._env = GodotEnv(
                ^^^^^^^^^
  File "/home/valapeos/.cache/pypoetry/virtualenvs/pneumarl-4s6AwDM4-py3.11/lib/python3.11/site-packages/godot_rl/core/godot_env.py", line 59, in __init__
    self.connection = self._start_server()
                      ^^^^^^^^^^^^^^^^^^^^
  File "/home/valapeos/.cache/pypoetry/virtualenvs/pneumarl-4s6AwDM4-py3.11/lib/python3.11/site-packages/godot_rl/core/godot_env.py", line 317, in _start_server
    connection, client_address = sock.accept()
                                 ^^^^^^^^^^^^^
  File "/nix/store/glfr70gi7hfaj50mwj2431p8bg60fhqw-python3-3.11.9/lib/python3.11/socket.py", line 294, in accept
    fd, addr = self._accept()
               ^^^^^^^^^^^^^^
TimeoutError: timed out
Exception raised in creation task: The actor died because of an error raised in its creation task, [36mray::PPO.__init__()[39m (pid=13649, ip=192.168.1.56, actor_id=0b0450d90a301440d0afa9f001000000, repr=PPO)
  File "/home/valapeos/.cache/pypoetry/virtualenvs/pneumarl-4s6AwDM4-py3.11/lib/python3.11/site-packages/ray/rllib/env/env_runner_group.py", line 239, in _setup
    self.add_workers(
  File "/home/valapeos/.cache/pypoetry/virtualenvs/pneumarl-4s6AwDM4-py3.11/lib/python3.11/site-packages/ray/rllib/env/env_runner_group.py", line 754, in add_workers
    raise result.get()
  File "/home/valapeos/.cache/pypoetry/virtualenvs/pneumarl-4s6AwDM4-py3.11/lib/python3.11/site-packages/ray/rllib/utils/actor_manager.py", line 497, in _fetch_result
    result = ray.get(r)
             ^^^^^^^^^^
           ^^^^^^^^^^^^^^^^^^^
           ^^^^^^^^^^^^^^^^^^^^^
                                  ^^^^^^^^^^^^^^^^^^^^^^^^^^^^^^^^^^^^^^^^^^^^^^^^
ray.exceptions.ActorDiedError: The actor died because of an error raised in its creation task, [36mray::RolloutWorker.__init__()[39m (pid=13721, ip=192.168.1.56, actor_id=cf76be01afb9954787ceb84801000000, repr=<ray.rllib.evaluation.rollout_worker.RolloutWorker object at 0x7fd32a36abd0>)
           ^^^^^^^^^^^^^^^^^^^^^^^^^^^^^^^^^^^^
           ^^^^^^^^^^^^^^^^^^^^^^^^^^^^^^^
  File "/home/valapeos/.cache/pypoetry/virtualenvs/pneumarl-4s6AwDM4-py3.11/lib/python3.11/site-packages/ray/rllib/evaluation/rollout_worker.py", line 407, in __init__
    self.env = env_creator(copy.deepcopy(self.env_context))
               ^^^^^^^^^^^^^^^^^^^^^^^^^^^^^^^^^^^^^^^^^^^^
  File "/home/valapeos/Projects/pneumarl/rllib_example.py", line 48, in env_creator
    return RayVectorGodotEnv(config=env_config, port=port, seed=seed)
           ^^^^^^^^^^^^^^^^^^^^^^^^^^^^^^^^^^^^^^^^^^^^^^^^^^^^^^^^^^
  File "/home/valapeos/.cache/pypoetry/virtualenvs/pneumarl-4s6AwDM4-py3.11/lib/python3.11/site-packages/godot_rl/wrappers/ray_wrapper.py", line 22, in __init__
    self._env = GodotEnv(
                ^^^^^^^^^
  File "/home/valapeos/.cache/pypoetry/virtualenvs/pneumarl-4s6AwDM4-py3.11/lib/python3.11/site-packages/godot_rl/core/godot_env.py", line 59, in __init__
    self.connection = self._start_server()
                      ^^^^^^^^^^^^^^^^^^^^
  File "/home/valapeos/.cache/pypoetry/virtualenvs/pneumarl-4s6AwDM4-py3.11/lib/python3.11/site-packages/godot_rl/core/godot_env.py", line 317, in _start_server
    connection, client_address = sock.accept()
                                 ^^^^^^^^^^^^^
  File "/nix/store/glfr70gi7hfaj50mwj2431p8bg60fhqw-python3-3.11.9/lib/python3.11/socket.py", line 294, in accept
    fd, addr = self._accept()
               ^^^^^^^^^^^^^^
TimeoutError: timed out

During handling of the above exception, another exception occurred:

[36mray::PPO.__init__()[39m (pid=13649, ip=192.168.1.56, actor_id=0b0450d90a301440d0afa9f001000000, repr=PPO)
           ^^^^^^^^^^^^^^^^^^^^^^^^^^^^^^^^^^^^
           ^^^^^^^^^^^^^^^^^^^^^^^^^^^^^^^
  File "/home/valapeos/.cache/pypoetry/virtualenvs/pneumarl-4s6AwDM4-py3.11/lib/python3.11/site-packages/ray/rllib/algorithms/algorithm.py", line 554, in __init__
    super().__init__(
  File "/home/valapeos/.cache/pypoetry/virtualenvs/pneumarl-4s6AwDM4-py3.11/lib/python3.11/site-packages/ray/tune/trainable/trainable.py", line 158, in __init__
    self.setup(copy.deepcopy(self.config))
           ^^^^^^^^^^^^^^^^^^^^^^^^^^^^^^^
  File "/home/valapeos/.cache/pypoetry/virtualenvs/pneumarl-4s6AwDM4-py3.11/lib/python3.11/site-packages/ray/rllib/algorithms/algorithm.py", line 640, in setup
    self.workers = EnvRunnerGroup(
                   ^^^^^^^^^^^^^^^
  File "/home/valapeos/.cache/pypoetry/virtualenvs/pneumarl-4s6AwDM4-py3.11/lib/python3.11/site-packages/ray/rllib/env/env_runner_group.py", line 191, in __init__
    raise e.args[0].args[2]
TimeoutError: timed out
